Workbook

Sheet Registro Proyectos
A1: REGISTRO DE PROYECTOS - ENLAZA GEB - Arquitectura C
A2: ID | B2: DATOS BASICOS | G2: UBICACION Y PDET | L2: SROI | O2: STAKEHOLDERS | T2: RIESGOS (Prob x Impacto 1-5) | AB2: COMITE
A3: ID | B3: Nombre del Proyecto | C3: Organizacion | D3: Presupuesto ($) | E3: Beneficiarios Directos | F3: Duracion (meses) | G3: Departamento | H3: Municipio | I3: Es PDET? | J3: Sector Principal | K3: Puntaje Sectorial | L3: Valor SROI | M3: Score SROI (0-100) | N3: Observaciones SROI | O3: Pertinencia Operac. (1-5) | P3: Mejora Relacion. (1-5) | Q3: Stakeholders Involucrados | R3: Corredor Transmision? | S3: Score Stakeholders (0-100) | T3: R.Tecnico Prob (1-5) | U3: R.Tecnico Impacto (1-5) | V3: R.Social Prob (1-5) | W3: R.Social Impacto (1-5) | X3: R.Financiero Prob (1-5) | Y3: R.Financiero Impacto (1-5) | Z3: R.Regulatorio Prob (1-5) | AA3: R.Regulatorio Impacto (1-5) | AB3: Score Riesgos (0-100) | AC3: SCORE TOTAL | AD3: NIVEL PRIORIDAD | AE3: Estado Comite
A4: =IF(B4="","",ROW()-3) | I4: =IF(H4="","",IF(COUNTIF(Catalogos!$A:$A,H4)>0,"SI","NO")) | K4: =IF(OR(H4="",J4=""),"",IFERROR(INDEX(Catalogos!$C:$C,MATCH(H4&"|"&J4,Catalogos!$D:$D,0)),0)) | M4: =IF(L4="","",IF(L4<1,0,MIN(ROUND(60+35*LN(L4)/LN(3),1),98))) | S4: =IF(OR(O4="",P4=""),"",ROUND(((O4/5)*100)*0.4+((P4/5)*100)*0.35+IF(R4="SI",100,0)*0.15+MIN(LEN(SUBSTITUTE(Q4," ",""))/3,1)*100*0.1,1)) | AB4: =IF(OR(T4="",V4="",X4="",Z4=""),"",ROUND(MAX(MIN(100-(T4*U4/25)*100,100),0)*0.3+MAX(MIN(100-(V4*W4/25)*100,100),0)*0.25+MAX(MIN(100-(X4*Y4/25)*100,100),0)*0.2+MAX(MIN(100-(Z4*AA4/25)*100,100),0)*0.15+10,1)) | AC4: =IF(OR(M4="",S4="",AB4=""),"",IF(M4=0,0,ROUND(M4*0.4+S4*0.25+(IF(I4="SI",ROUND(70*0.2+((5+IF(K4="",5,K4))/20)*100*0.8,1),50))*0.2+AB4*0.15,1))) | AD4: =IF(AC4="","",IF(M4=0,"RECHAZADO",IF(AC4>=85,"MUY ALTA",IF(AC4>=70,"ALTA",IF(AC4>=50,"MEDIA","BAJA")))))
A5: =IF(B5="","",ROW()-3) | I5: =IF(H5="","",IF(COUNTIF(Catalogos!$A:$A,H5)>0,"SI","NO")) | K5: =IF(OR(H5="",J5=""),"",IFERROR(INDEX(Catalogos!$C:$C,MATCH(H5&"|"&J5,Catalogos!$D:$D,0)),0)) | M5: =IF(L5="","",IF(L5<1,0,MIN(ROUND(60+35*LN(L5)/LN(3),1),98))) | S5: =IF(OR(O5="",P5=""),"",ROUND(((O5/5)*100)*0.4+((P5/5)*100)*0.35+IF(R5="SI",100,0)*0.15+MIN(LEN(SUBSTITUTE(Q5," ",""))/3,1)*100*0.1,1)) | AB5: =IF(OR(T5="",V5="",X5="",Z5=""),"",ROUND(MAX(MIN(100-(T5*U5/25)*100,100),0)*0.3+MAX(MIN(100-(V5*W5/25)*100,100),0)*0.25+MAX(MIN(100-(X5*Y5/25)*100,100),0)*0.2+MAX(MIN(100-(Z5*AA5/25)*100,100),0)*0.15+10,1)) | AC5: =IF(OR(M5="",S5="",AB5=""),"",IF(M5=0,0,ROUND(M5*0.4+S5*0.25+(IF(I5="SI",ROUND(70*0.2+((5+IF(K5="",5,K5))/20)*100*0.8,1),50))*0.2+AB5*0.15,1))) | AD5: =IF(AC5="","",IF(M5=0,"RECHAZADO",IF(AC5>=85,"MUY ALTA",IF(AC5>=70,"ALTA",IF(AC5>=50,"MEDIA","BAJA")))))
A6: =IF(B6="","",ROW()-3) | I6: =IF(H6="","",IF(COUNTIF(Catalogos!$A:$A,H6)>0,"SI","NO")) | K6: =IF(OR(H6="",J6=""),"",IFERROR(INDEX(Catalogos!$C:$C,MATCH(H6&"|"&J6,Catalogos!$D:$D,0)),0)) | M6: =IF(L6="","",IF(L6<1,0,MIN(ROUND(60+35*LN(L6)/LN(3),1),98))) | S6: =IF(OR(O6="",P6=""),"",ROUND(((O6/5)*100)*0.4+((P6/5)*100)*0.35+IF(R6="SI",100,0)*0.15+MIN(LEN(SUBSTITUTE(Q6," ",""))/3,1)*100*0.1,1)) | AB6: =IF(OR(T6="",V6="",X6="",Z6=""),"",ROUND(MAX(MIN(100-(T6*U6/25)*100,100),0)*0.3+MAX(MIN(100-(V6*W6/25)*100,100),0)*0.25+MAX(MIN(100-(X6*Y6/25)*100,100),0)*0.2+MAX(MIN(100-(Z6*AA6/25)*100,100),0)*0.15+10,1)) | AC6: =IF(OR(M6="",S6="",AB6=""),"",IF(M6=0,0,ROUND(M6*0.4+S6*0.25+(IF(I6="SI",ROUND(70*0.2+((5+IF(K6="",5,K6))/20)*100*0.8,1),50))*0.2+AB6*0.15,1))) | AD6: =IF(AC6="","",IF(M6=0,"RECHAZADO",IF(AC6>=85,"MUY ALTA",IF(AC6>=70,"ALTA",IF(AC6>=50,"MEDIA","BAJA")))))
A7: =IF(B7="","",ROW()-3) | I7: =IF(H7="","",IF(COUNTIF(Catalogos!$A:$A,H7)>0,"SI","NO")) | K7: =IF(OR(H7="",J7=""),"",IFERROR(INDEX(Catalogos!$C:$C,MATCH(H7&"|"&J7,Catalogos!$D:$D,0)),0)) | M7: =IF(L7="","",IF(L7<1,0,MIN(ROUND(60+35*LN(L7)/LN(3),1),98))) | S7: =IF(OR(O7="",P7=""),"",ROUND(((O7/5)*100)*0.4+((P7/5)*100)*0.35+IF(R7="SI",100,0)*0.15+MIN(LEN(SUBSTITUTE(Q7," ",""))/3,1)*100*0.1,1)) | AB7: =IF(OR(T7="",V7="",X7="",Z7=""),"",ROUND(MAX(MIN(100-(T7*U7/25)*100,100),0)*0.3+MAX(MIN(100-(V7*W7/25)*100,100),0)*0.25+MAX(MIN(100-(X7*Y7/25)*100,100),0)*0.2+MAX(MIN(100-(Z7*AA7/25)*100,100),0)*0.15+10,1)) | AC7: =IF(OR(M7="",S7="",AB7=""),"",IF(M7=0,0,ROUND(M7*0.4+S7*0.25+(IF(I7="SI",ROUND(70*0.2+((5+IF(K7="",5,K7))/20)*100*0.8,1),50))*0.2+AB7*0.15,1))) | AD7: =IF(AC7="","",IF(M7=0,"RECHAZADO",IF(AC7>=85,"MUY ALTA",IF(AC7>=70,"ALTA",IF(AC7>=50,"MEDIA","BAJA")))))
A8: =IF(B8="","",ROW()-3) | I8: =IF(H8="","",IF(COUNTIF(Catalogos!$A:$A,H8)>0,"SI","NO")) | K8: =IF(OR(H8="",J8=""),"",IFERROR(INDEX(Catalogos!$C:$C,MATCH(H8&"|"&J8,Catalogos!$D:$D,0)),0)) | M8: =IF(L8="","",IF(L8<1,0,MIN(ROUND(60+35*LN(L8)/LN(3),1),98))) | S8: =IF(OR(O8="",P8=""),"",ROUND(((O8/5)*100)*0.4+((P8/5)*100)*0.35+IF(R8="SI",100,0)*0.15+MIN(LEN(SUBSTITUTE(Q8," ",""))/3,1)*100*0.1,1)) | AB8: =IF(OR(T8="",V8="",X8="",Z8=""),"",ROUND(MAX(MIN(100-(T8*U8/25)*100,100),0)*0.3+MAX(MIN(100-(V8*W8/25)*100,100),0)*0.25+MAX(MIN(100-(X8*Y8/25)*100,100),0)*0.2+MAX(MIN(100-(Z8*AA8/25)*100,100),0)*0.15+10,1)) | AC8: =IF(OR(M8="",S8="",AB8=""),"",IF(M8=0,0,ROUND(M8*0.4+S8*0.25+(IF(I8="SI",ROUND(70*0.2+((5+IF(K8="",5,K8))/20)*100*0.8,1),50))*0.2+AB8*0.15,1))) | AD8: =IF(AC8="","",IF(M8=0,"RECHAZADO",IF(AC8>=85,"MUY ALTA",IF(AC8>=70,"ALTA",IF(AC8>=50,"MEDIA","BAJA")))))
A9: =IF(B9="","",ROW()-3) | I9: =IF(H9="","",IF(COUNTIF(Catalogos!$A:$A,H9)>0,"SI","NO")) | K9: =IF(OR(H9="",J9=""),"",IFERROR(INDEX(Catalogos!$C:$C,MATCH(H9&"|"&J9,Catalogos!$D:$D,0)),0)) | M9: =IF(L9="","",IF(L9<1,0,MIN(ROUND(60+35*LN(L9)/LN(3),1),98))) | S9: =IF(OR(O9="",P9=""),"",ROUND(((O9/5)*100)*0.4+((P9/5)*100)*0.35+IF(R9="SI",100,0)*0.15+MIN(LEN(SUBSTITUTE(Q9," ",""))/3,1)*100*0.1,1)) | AB9: =IF(OR(T9="",V9="",X9="",Z9=""),"",ROUND(MAX(MIN(100-(T9*U9/25)*100,100),0)*0.3+MAX(MIN(100-(V9*W9/25)*100,100),0)*0.25+MAX(MIN(100-(X9*Y9/25)*100,100),0)*0.2+MAX(MIN(100-(Z9*AA9/25)*100,100),0)*0.15+10,1)) | AC9: =IF(OR(M9="",S9="",AB9=""),"",IF(M9=0,0,ROUND(M9*0.4+S9*0.25+(IF(I9="SI",ROUND(70*0.2+((5+IF(K9="",5,K9))/20)*100*0.8,1),50))*0.2+AB9*0.15,1))) | AD9: =IF(AC9="","",IF(M9=0,"RECHAZADO",IF(AC9>=85,"MUY ALTA",IF(AC9>=70,"ALTA",IF(AC9>=50,"MEDIA","BAJA")))))
A10: =IF(B10="","",ROW()-3) | I10: =IF(H10="","",IF(COUNTIF(Catalogos!$A:$A,H10)>0,"SI","NO")) | K10: =IF(OR(H10="",J10=""),"",IFERROR(INDEX(Catalogos!$C:$C,MATCH(H10&"|"&J10,Catalogos!$D:$D,0)),0)) | M10: =IF(L10="","",IF(L10<1,0,MIN(ROUND(60+35*LN(L10)/LN(3),1),98))) | S10: =IF(OR(O10="",P10=""),"",ROUND(((O10/5)*100)*0.4+((P10/5)*100)*0.35+IF(R10="SI",100,0)*0.15+MIN(LEN(SUBSTITUTE(Q10," ",""))/3,1)*100*0.1,1)) | AB10: =IF(OR(T10="",V10="",X10="",Z10=""),"",ROUND(MAX(MIN(100-(T10*U10/25)*100,100),0)*0.3+MAX(MIN(100-(V10*W10/25)*100,100),0)*0.25+MAX(MIN(100-(X10*Y10/25)*100,100),0)*0.2+MAX(MIN(100-(Z10*AA10/25)*100,100),0)*0.15+10,1)) | AC10: =IF(OR(M10="",S10="",AB10=""),"",IF(M10=0,0,ROUND(M10*0.4+S10*0.25+(IF(I10="SI",ROUND(70*0.2+((5+IF(K10="",5,K10))/20)*100*0.8,1),50))*0.2+AB10*0.15,1))) | AD10: =IF(AC10="","",IF(M10=0,"RECHAZADO",IF(AC10>=85,"MUY ALTA",IF(AC10>=70,"ALTA",IF(AC10>=50,"MEDIA","BAJA")))))
A11: =IF(B11="","",ROW()-3) | I11: =IF(H11="","",IF(COUNTIF(Catalogos!$A:$A,H11)>0,"SI","NO")) | K11: =IF(OR(H11="",J11=""),"",IFERROR(INDEX(Catalogos!$C:$C,MATCH(H11&"|"&J11,Catalogos!$D:$D,0)),0)) | M11: =IF(L11="","",IF(L11<1,0,MIN(ROUND(60+35*LN(L11)/LN(3),1),98))) | S11: =IF(OR(O11="",P11=""),"",ROUND(((O11/5)*100)*0.4+((P11/5)*100)*0.35+IF(R11="SI",100,0)*0.15+MIN(LEN(SUBSTITUTE(Q11," ",""))/3,1)*100*0.1,1)) | AB11: =IF(OR(T11="",V11="",X11="",Z11=""),"",ROUND(MAX(MIN(100-(T11*U11/25)*100,100),0)*0.3+MAX(MIN(100-(V11*W11/25)*100,100),0)*0.25+MAX(MIN(100-(X11*Y11/25)*100,100),0)*0.2+MAX(MIN(100-(Z11*AA11/25)*100,100),0)*0.15+10,1)) | AC11: =IF(OR(M11="",S11="",AB11=""),"",IF(M11=0,0,ROUND(M11*0.4+S11*0.25+(IF(I11="SI",ROUND(70*0.2+((5+IF(K11="",5,K11))/20)*100*0.8,1),50))*0.2+AB11*0.15,1))) | AD11: =IF(AC11="","",IF(M11=0,"RECHAZADO",IF(AC11>=85,"MUY ALTA",IF(AC11>=70,"ALTA",IF(AC11>=50,"MEDIA","BAJA")))))
A12: =IF(B12="","",ROW()-3) | I12: =IF(H12="","",IF(COUNTIF(Catalogos!$A:$A,H12)>0,"SI","NO")) | K12: =IF(OR(H12="",J12=""),"",IFERROR(INDEX(Catalogos!$C:$C,MATCH(H12&"|"&J12,Catalogos!$D:$D,0)),0)) | M12: =IF(L12="","",IF(L12<1,0,MIN(ROUND(60+35*LN(L12)/LN(3),1),98))) | S12: =IF(OR(O12="",P12=""),"",ROUND(((O12/5)*100)*0.4+((P12/5)*100)*0.35+IF(R12="SI",100,0)*0.15+MIN(LEN(SUBSTITUTE(Q12," ",""))/3,1)*100*0.1,1)) | AB12: =IF(OR(T12="",V12="",X12="",Z12=""),"",ROUND(MAX(MIN(100-(T12*U12/25)*100,100),0)*0.3+MAX(MIN(100-(V12*W12/25)*100,100),0)*0.25+MAX(MIN(100-(X12*Y12/25)*100,100),0)*0.2+MAX(MIN(100-(Z12*AA12/25)*100,100),0)*0.15+10,1)) | AC12: =IF(OR(M12="",S12="",AB12=""),"",IF(M12=0,0,ROUND(M12*0.4+S12*0.25+(IF(I12="SI",ROUND(70*0.2+((5+IF(K12="",5,K12))/20)*100*0.8,1),50))*0.2+AB12*0.15,1))) | AD12: =IF(AC12="","",IF(M12=0,"RECHAZADO",IF(AC12>=85,"MUY ALTA",IF(AC12>=70,"ALTA",IF(AC12>=50,"MEDIA","BAJA")))))
A13: =IF(B13="","",ROW()-3) | I13: =IF(H13="","",IF(COUNTIF(Catalogos!$A:$A,H13)>0,"SI","NO")) | K13: =IF(OR(H13="",J13=""),"",IFERROR(INDEX(Catalogos!$C:$C,MATCH(H13&"|"&J13,Catalogos!$D:$D,0)),0)) | M13: =IF(L13="","",IF(L13<1,0,MIN(ROUND(60+35*LN(L13)/LN(3),1),98))) | S13: =IF(OR(O13="",P13=""),"",ROUND(((O13/5)*100)*0.4+((P13/5)*100)*0.35+IF(R13="SI",100,0)*0.15+MIN(LEN(SUBSTITUTE(Q13," ",""))/3,1)*100*0.1,1)) | AB13: =IF(OR(T13="",V13="",X13="",Z13=""),"",ROUND(MAX(MIN(100-(T13*U13/25)*100,100),0)*0.3+MAX(MIN(100-(V13*W13/25)*100,100),0)*0.25+MAX(MIN(100-(X13*Y13/25)*100,100),0)*0.2+MAX(MIN(100-(Z13*AA13/25)*100,100),0)*0.15+10,1)) | AC13: =IF(OR(M13="",S13="",AB13=""),"",IF(M13=0,0,ROUND(M13*0.4+S13*0.25+(IF(I13="SI",ROUND(70*0.2+((5+IF(K13="",5,K13))/20)*100*0.8,1),50))*0.2+AB13*0.15,1))) | AD13: =IF(AC13="","",IF(M13=0,"RECHAZADO",IF(AC13>=85,"MUY ALTA",IF(AC13>=70,"ALTA",IF(AC13>=50,"MEDIA","BAJA")))))
A14: =IF(B14="","",ROW()-3) | I14: =IF(H14="","",IF(COUNTIF(Catalogos!$A:$A,H14)>0,"SI","NO")) | K14: =IF(OR(H14="",J14=""),"",IFERROR(INDEX(Catalogos!$C:$C,MATCH(H14&"|"&J14,Catalogos!$D:$D,0)),0)) | M14: =IF(L14="","",IF(L14<1,0,MIN(ROUND(60+35*LN(L14)/LN(3),1),98))) | S14: =IF(OR(O14="",P14=""),"",ROUND(((O14/5)*100)*0.4+((P14/5)*100)*0.35+IF(R14="SI",100,0)*0.15+MIN(LEN(SUBSTITUTE(Q14," ",""))/3,1)*100*0.1,1)) | AB14: =IF(OR(T14="",V14="",X14="",Z14=""),"",ROUND(MAX(MIN(100-(T14*U14/25)*100,100),0)*0.3+MAX(MIN(100-(V14*W14/25)*100,100),0)*0.25+MAX(MIN(100-(X14*Y14/25)*100,100),0)*0.2+MAX(MIN(100-(Z14*AA14/25)*100,100),0)*0.15+10,1)) | AC14: =IF(OR(M14="",S14="",AB14=""),"",IF(M14=0,0,ROUND(M14*0.4+S14*0.25+(IF(I14="SI",ROUND(70*0.2+((5+IF(K14="",5,K14))/20)*100*0.8,1),50))*0.2+AB14*0.15,1))) | AD14: =IF(AC14="","",IF(M14=0,"RECHAZADO",IF(AC14>=85,"MUY ALTA",IF(AC14>=70,"ALTA",IF(AC14>=50,"MEDIA","BAJA")))))
A15: =IF(B15="","",ROW()-3) | I15: =IF(H15="","",IF(COUNTIF(Catalogos!$A:$A,H15)>0,"SI","NO")) | K15: =IF(OR(H15="",J15=""),"",IFERROR(INDEX(Catalogos!$C:$C,MATCH(H15&"|"&J15,Catalogos!$D:$D,0)),0)) | M15: =IF(L15="","",IF(L15<1,0,MIN(ROUND(60+35*LN(L15)/LN(3),1),98))) | S15: =IF(OR(O15="",P15=""),"",ROUND(((O15/5)*100)*0.4+((P15/5)*100)*0.35+IF(R15="SI",100,0)*0.15+MIN(LEN(SUBSTITUTE(Q15," ",""))/3,1)*100*0.1,1)) | AB15: =IF(OR(T15="",V15="",X15="",Z15=""),"",ROUND(MAX(MIN(100-(T15*U15/25)*100,100),0)*0.3+MAX(MIN(100-(V15*W15/25)*100,100),0)*0.25+MAX(MIN(100-(X15*Y15/25)*100,100),0)*0.2+MAX(MIN(100-(Z15*AA15/25)*100,100),0)*0.15+10,1)) | AC15: =IF(OR(M15="",S15="",AB15=""),"",IF(M15=0,0,ROUND(M15*0.4+S15*0.25+(IF(I15="SI",ROUND(70*0.2+((5+IF(K15="",5,K15))/20)*100*0.8,1),50))*0.2+AB15*0.15,1))) | AD15: =IF(AC15="","",IF(M15=0,"RECHAZADO",IF(AC15>=85,"MUY ALTA",IF(AC15>=70,"ALTA",IF(AC15>=50,"MEDIA","BAJA")))))
... A53: =IF(B53="","",ROW()-3) | I53: =IF(H53="","",IF(COUNTIF(Catalogos!$A:$A,H53)>0,"SI","NO")) | K53: =IF(OR(H53="",J53=""),"",IFERROR(INDEX(Catalogos!$C:$C,MATCH(H53&"|"&J53,Catalogos!$D:$D,0)),0)) | M53: =IF(L53="","",IF(L53<1,0,MIN(ROUND(60+35*LN(L53)/LN(3),1),98))) | S53: =IF(OR(O53="",P53=""),"",ROUND(((O53/5)*100)*0.4+((P53/5)*100)*0.35+IF(R53="SI",100,0)*0.15+MIN(LEN(SUBSTITUTE(Q53," ",""))/3,1)*100*0.1,1)) | AB53: =IF(OR(T53="",V53="",X53="",Z53=""),"",ROUND(MAX(MIN(100-(T53*U53/25)*100,100),0)*0.3+MAX(MIN(100-(V53*W53/25)*100,100),0)*0.25+MAX(MIN(100-(X53*Y53/25)*100,100),0)*0.2+MAX(MIN(100-(Z53*AA53/25)*100,100),0)*0.15+10,1)) | AC53: =IF(OR(M53="",S53="",AB53=""),"",IF(M53=0,0,ROUND(M53*0.4+S53*0.25+(IF(I53="SI",ROUND(70*0.2+((5+IF(K53="",5,K53))/20)*100*0.8,1),50))*0.2+AB53*0.15,1))) | AD53: =IF(AC53="","",IF(M53=0,"RECHAZADO",IF(AC53>=85,"MUY ALTA",IF(AC53>=70,"ALTA",IF(AC53>=50,"MEDIA","BAJA")))))

Sheet Evaluacion Detallada
A1: EVALUACION DETALLADA - SCORING ARQUITECTURA C
A2: ID | B2: Proyecto | C2: Score SROI (40%) | D2: Contrib. SROI | E2: Score Stakeholders (25%) | F2: Contrib. Stakeholders | G2: Score Prob. CONFIS (20%) | H2: Contrib. Prob.Aprob | I2: Score Riesgos (15%) | J2: Contrib. Riesgos | K2: SCORE TOTAL | L2: NIVEL
A3: =IF('Registro Proyectos'!B4="","",ROW()-2) | B3: =IF('Registro Proyectos'!B4="","",'Registro Proyectos'!B4) | C3: =IF(B3="","",'Registro Proyectos'!M4) | D3: =IF(C3="","",ROUND(C3*0.4,1)) | E3: =IF(B3="","",'Registro Proyectos'!S4) | F3: =IF(E3="","",ROUND(E3*0.25,1)) | G3: =IF(B3="","",IF('Registro Proyectos'!I4="SI",ROUND(70*0.2+((5+IF('Registro Proyectos'!K4="",5,'Registro Proyectos'!K4))/20)*100*0.8,1),50)) | H3: =IF(G3="","",ROUND(G3*0.2,1)) | I3: =IF(B3="","",'Registro Proyectos'!AB4) | J3: =IF(I3="","",ROUND(I3*0.15,1)) | K3: =IF(B3="","",'Registro Proyectos'!AC4) | L3: =IF(K3="","",IF(C3=0,"RECHAZADO",IF(K3>=85,"MUY ALTA",IF(K3>=70,"ALTA",IF(K3>=50,"MEDIA","BAJA")))))
A4: =IF('Registro Proyectos'!B5="","",ROW()-2) | B4: =IF('Registro Proyectos'!B5="","",'Registro Proyectos'!B5) | C4: =IF(B4="","",'Registro Proyectos'!M5) | D4: =IF(C4="","",ROUND(C4*0.4,1)) | E4: =IF(B4="","",'Registro Proyectos'!S5) | F4: =IF(E4="","",ROUND(E4*0.25,1)) | G4: =IF(B4="","",IF('Registro Proyectos'!I5="SI",ROUND(70*0.2+((5+IF('Registro Proyectos'!K5="",5,'Registro Proyectos'!K5))/20)*100*0.8,1),50)) | H4: =IF(G4="","",ROUND(G4*0.2,1)) | I4: =IF(B4="","",'Registro Proyectos'!AB5) | J4: =IF(I4="","",ROUND(I4*0.15,1)) | K4: =IF(B4="","",'Registro Proyectos'!AC5) | L4: =IF(K4="","",IF(C4=0,"RECHAZADO",IF(K4>=85,"MUY ALTA",IF(K4>=70,"ALTA",IF(K4>=50,"MEDIA","BAJA")))))
A5: =IF('Registro Proyectos'!B6="","",ROW()-2) | B5: =IF('Registro Proyectos'!B6="","",'Registro Proyectos'!B6) | C5: =IF(B5="","",'Registro Proyectos'!M6) | D5: =IF(C5="","",ROUND(C5*0.4,1)) | E5: =IF(B5="","",'Registro Proyectos'!S6) | F5: =IF(E5="","",ROUND(E5*0.25,1)) | G5: =IF(B5="","",IF('Registro Proyectos'!I6="SI",ROUND(70*0.2+((5+IF('Registro Proyectos'!K6="",5,'Registro Proyectos'!K6))/20)*100*0.8,1),50)) | H5: =IF(G5="","",ROUND(G5*0.2,1)) | I5: =IF(B5="","",'Registro Proyectos'!AB6) | J5: =IF(I5="","",ROUND(I5*0.15,1)) | K5: =IF(B5="","",'Registro Proyectos'!AC6) | L5: =IF(K5="","",IF(C5=0,"RECHAZADO",IF(K5>=85,"MUY ALTA",IF(K5>=70,"ALTA",IF(K5>=50,"MEDIA","BAJA")))))
A6: =IF('Registro Proyectos'!B7="","",ROW()-2) | B6: =IF('Registro Proyectos'!B7="","",'Registro Proyectos'!B7) | C6: =IF(B6="","",'Registro Proyectos'!M7) | D6: =IF(C6="","",ROUND(C6*0.4,1)) | E6: =IF(B6="","",'Registro Proyectos'!S7) | F6: =IF(E6="","",ROUND(E6*0.25,1)) | G6: =IF(B6="","",IF('Registro Proyectos'!I7="SI",ROUND(70*0.2+((5+IF('Registro Proyectos'!K7="",5,'Registro Proyectos'!K7))/20)*100*0.8,1),50)) | H6: =IF(G6="","",ROUND(G6*0.2,1)) | I6: =IF(B6="","",'Registro Proyectos'!AB7) | J6: =IF(I6="","",ROUND(I6*0.15,1)) | K6: =IF(B6="","",'Registro Proyectos'!AC7) | L6: =IF(K6="","",IF(C6=0,"RECHAZADO",IF(K6>=85,"MUY ALTA",IF(K6>=70,"ALTA",IF(K6>=50,"MEDIA","BAJA")))))
A7: =IF('Registro Proyectos'!B8="","",ROW()-2) | B7: =IF('Registro Proyectos'!B8="","",'Registro Proyectos'!B8) | C7: =IF(B7="","",'Registro Proyectos'!M8) | D7: =IF(C7="","",ROUND(C7*0.4,1)) | E7: =IF(B7="","",'Registro Proyectos'!S8) | F7: =IF(E7="","",ROUND(E7*0.25,1)) | G7: =IF(B7="","",IF('Registro Proyectos'!I8="SI",ROUND(70*0.2+((5+IF('Registro Proyectos'!K8="",5,'Registro Proyectos'!K8))/20)*100*0.8,1),50)) | H7: =IF(G7="","",ROUND(G7*0.2,1)) | I7: =IF(B7="","",'Registro Proyectos'!AB8) | J7: =IF(I7="","",ROUND(I7*0.15,1)) | K7: =IF(B7="","",'Registro Proyectos'!AC8) | L7: =IF(K7="","",IF(C7=0,"RECHAZADO",IF(K7>=85,"MUY ALTA",IF(K7>=70,"ALTA",IF(K7>=50,"MEDIA","BAJA")))))
A8: =IF('Registro Proyectos'!B9="","",ROW()-2) | B8: =IF('Registro Proyectos'!B9="","",'Registro Proyectos'!B9) | C8: =IF(B8="","",'Registro Proyectos'!M9) | D8: =IF(C8="","",ROUND(C8*0.4,1)) | E8: =IF(B8="","",'Registro Proyectos'!S9) | F8: =IF(E8="","",ROUND(E8*0.25,1)) | G8: =IF(B8="","",IF('Registro Proyectos'!I9="SI",ROUND(70*0.2+((5+IF('Registro Proyectos'!K9="",5,'Registro Proyectos'!K9))/20)*100*0.8,1),50)) | H8: =IF(G8="","",ROUND(G8*0.2,1)) | I8: =IF(B8="","",'Registro Proyectos'!AB9) | J8: =IF(I8="","",ROUND(I8*0.15,1)) | K8: =IF(B8="","",'Registro Proyectos'!AC9) | L8: =IF(K8="","",IF(C8=0,"RECHAZADO",IF(K8>=85,"MUY ALTA",IF(K8>=70,"ALTA",IF(K8>=50,"MEDIA","BAJA")))))
A9: =IF('Registro Proyectos'!B10="","",ROW()-2) | B9: =IF('Registro Proyectos'!B10="","",'Registro Proyectos'!B10) | C9: =IF(B9="","",'Registro Proyectos'!M10) | D9: =IF(C9="","",ROUND(C9*0.4,1)) | E9: =IF(B9="","",'Registro Proyectos'!S10) | F9: =IF(E9="","",ROUND(E9*0.25,1)) | G9: =IF(B9="","",IF('Registro Proyectos'!I10="SI",ROUND(70*0.2+((5+IF('Registro Proyectos'!K10="",5,'Registro Proyectos'!K10))/20)*100*0.8,1),50)) | H9: =IF(G9="","",ROUND(G9*0.2,1)) | I9: =IF(B9="","",'Registro Proyectos'!AB10) | J9: =IF(I9="","",ROUND(I9*0.15,1)) | K9: =IF(B9="","",'Registro Proyectos'!AC10) | L9: =IF(K9="","",IF(C9=0,"RECHAZADO",IF(K9>=85,"MUY ALTA",IF(K9>=70,"ALTA",IF(K9>=50,"MEDIA","BAJA")))))
A10: =IF('Registro Proyectos'!B11="","",ROW()-2) | B10: =IF('Registro Proyectos'!B11="","",'Registro Proyectos'!B11) | C10: =IF(B10="","",'Registro Proyectos'!M11) | D10: =IF(C10="","",ROUND(C10*0.4,1)) | E10: =IF(B10="","",'Registro Proyectos'!S11) | F10: =IF(E10="","",ROUND(E10*0.25,1)) | G10: =IF(B10="","",IF('Registro Proyectos'!I11="SI",ROUND(70*0.2+((5+IF('Registro Proyectos'!K11="",5,'Registro Proyectos'!K11))/20)*100*0.8,1),50)) | H10: =IF(G10="","",ROUND(G10*0.2,1)) | I10: =IF(B10="","",'Registro Proyectos'!AB11) | J10: =IF(I10="","",ROUND(I10*0.15,1)) | K10: =IF(B10="","",'Registro Proyectos'!AC11) | L10: =IF(K10="","",IF(C10=0,"RECHAZADO",IF(K10>=85,"MUY ALTA",IF(K10>=70,"ALTA",IF(K10>=50,"MEDIA","BAJA")))))
A11: =IF('Registro Proyectos'!B12="","",ROW()-2) | B11: =IF('Registro Proyectos'!B12="","",'Registro Proyectos'!B12) | C11: =IF(B11="","",'Registro Proyectos'!M12) | D11: =IF(C11="","",ROUND(C11*0.4,1)) | E11: =IF(B11="","",'Registro Proyectos'!S12) | F11: =IF(E11="","",ROUND(E11*0.25,1)) | G11: =IF(B11="","",IF('Registro Proyectos'!I12="SI",ROUND(70*0.2+((5+IF('Registro Proyectos'!K12="",5,'Registro Proyectos'!K12))/20)*100*0.8,1),50)) | H11: =IF(G11="","",ROUND(G11*0.2,1)) | I11: =IF(B11="","",'Registro Proyectos'!AB12) | J11: =IF(I11="","",ROUND(I11*0.15,1)) | K11: =IF(B11="","",'Registro Proyectos'!AC12) | L11: =IF(K11="","",IF(C11=0,"RECHAZADO",IF(K11>=85,"MUY ALTA",IF(K11>=70,"ALTA",IF(K11>=50,"MEDIA","BAJA")))))
A12: =IF('Registro Proyectos'!B13="","",ROW()-2) | B12: =IF('Registro Proyectos'!B13="","",'Registro Proyectos'!B13) | C12: =IF(B12="","",'Registro Proyectos'!M13) | D12: =IF(C12="","",ROUND(C12*0.4,1)) | E12: =IF(B12="","",'Registro Proyectos'!S13) | F12: =IF(E12="","",ROUND(E12*0.25,1)) | G12: =IF(B12="","",IF('Registro Proyectos'!I13="SI",ROUND(70*0.2+((5+IF('Registro Proyectos'!K13="",5,'Registro Proyectos'!K13))/20)*100*0.8,1),50)) | H12: =IF(G12="","",ROUND(G12*0.2,1)) | I12: =IF(B12="","",'Registro Proyectos'!AB13) | J12: =IF(I12="","",ROUND(I12*0.15,1)) | K12: =IF(B12="","",'Registro Proyectos'!AC13) | L12: =IF(K12="","",IF(C12=0,"RECHAZADO",IF(K12>=85,"MUY ALTA",IF(K12>=70,"ALTA",IF(K12>=50,"MEDIA","BAJA")))))
A13: =IF('Registro Proyectos'!B14="","",ROW()-2) | B13: =IF('Registro Proyectos'!B14="","",'Registro Proyectos'!B14) | C13: =IF(B13="","",'Registro Proyectos'!M14) | D13: =IF(C13="","",ROUND(C13*0.4,1)) | E13: =IF(B13="","",'Registro Proyectos'!S14) | F13: =IF(E13="","",ROUND(E13*0.25,1)) | G13: =IF(B13="","",IF('Registro Proyectos'!I14="SI",ROUND(70*0.2+((5+IF('Registro Proyectos'!K14="",5,'Registro Proyectos'!K14))/20)*100*0.8,1),50)) | H13: =IF(G13="","",ROUND(G13*0.2,1)) | I13: =IF(B13="","",'Registro Proyectos'!AB14) | J13: =IF(I13="","",ROUND(I13*0.15,1)) | K13: =IF(B13="","",'Registro Proyectos'!AC14) | L13: =IF(K13="","",IF(C13=0,"RECHAZADO",IF(K13>=85,"MUY ALTA",IF(K13>=70,"ALTA",IF(K13>=50,"MEDIA","BAJA")))))
A14: =IF('Registro Proyectos'!B15="","",ROW()-2) | B14: =IF('Registro Proyectos'!B15="","",'Registro Proyectos'!B15) | C14: =IF(B14="","",'Registro Proyectos'!M15) | D14: =IF(C14="","",ROUND(C14*0.4,1)) | E14: =IF(B14="","",'Registro Proyectos'!S15) | F14: =IF(E14="","",ROUND(E14*0.25,1)) | G14: =IF(B14="","",IF('Registro Proyectos'!I15="SI",ROUND(70*0.2+((5+IF('Registro Proyectos'!K15="",5,'Registro Proyectos'!K15))/20)*100*0.8,1),50)) | H14: =IF(G14="","",ROUND(G14*0.2,1)) | I14: =IF(B14="","",'Registro Proyectos'!AB15) | J14: =IF(I14="","",ROUND(I14*0.15,1)) | K14: =IF(B14="","",'Registro Proyectos'!AC15) | L14: =IF(K14="","",IF(C14=0,"RECHAZADO",IF(K14>=85,"MUY ALTA",IF(K14>=70,"ALTA",IF(K14>=50,"MEDIA","BAJA")))))
... A52: =IF('Registro Proyectos'!B53="","",ROW()-2) | B52: =IF('Registro Proyectos'!B53="","",'Registro Proyectos'!B53) | C52: =IF(B52="","",'Registro Proyectos'!M53) | D52: =IF(C52="","",ROUND(C52*0.4,1)) | E52: =IF(B52="","",'Registro Proyectos'!S53) | F52: =IF(E52="","",ROUND(E52*0.25,1)) | G52: =IF(B52="","",IF('Registro Proyectos'!I53="SI",ROUND(70*0.2+((5+IF('Registro Proyectos'!K53="",5,'Registro Proyectos'!K53))/20)*100*0.8,1),50)) | H52: =IF(G52="","",ROUND(G52*0.2,1)) | I52: =IF(B52="","",'Registro Proyectos'!AB53) | J52: =IF(I52="","",ROUND(I52*0.15,1)) | K52: =IF(B52="","",'Registro Proyectos'!AC53) | L52: =IF(K52="","",IF(C52=0,"RECHAZADO",IF(K52>=85,"MUY ALTA",IF(K52>=70,"ALTA",IF(K52>=50,"MEDIA","BAJA")))))

Sheet Catalogos
A1: Municipio PDET | B1: Departamento | C1: Puntaje | D1: Llave (Mun|Sector) | F1: ESCALAS DE EVALUACION
A2: Agustin Codazzi | B2: Cesar | C2: 6 | D2: Agustin Codazzi|Educacion | F2: PERTINENCIA OPERACIONAL (Rubrica Objetiva)
A3: Agustin Codazzi | B3: Cesar | C3: 3 | D3: Agustin Codazzi|Salud | F3: 5 | G3: Muy Alta | H3: Impacta directamente operacion de linea de transmision activa. Sin licencia social la operacion se detiene.
A4: Agustin Codazzi | B4: Cesar | C4: 9 | D4: Agustin Codazzi|Infraestructura Rural | F4: 4 | G4: Alta | H4: Territorio con comunidades que afectan planificacion de futuras lineas. Influencia significativa en reputacion.
A5: Agustin Codazzi | B5: Cesar | C5: 7 | D5: Agustin Codazzi|Agua y Saneamiento | F5: 3 | G5: Media | H5: Area de influencia indirecta. Contribuye a imagen corporativa pero no critico para operaciones.
A6: Valledupar | B6: Cesar | C6: 5 | D6: Valledupar|Educacion | F6: 2 | G6: Baja | H6: Fuera de corredores operacionales. Beneficio marginal para relacionamiento institucional.
A7: Valledupar | B7: Cesar | C7: 4 | D7: Valledupar|Salud | F7: 1 | G7: Nula | H7: Sin conexion con operaciones, corredores ni territorios estrategicos de ENLAZA.
A8: Valledupar | B8: Cesar | C8: 8 | D8: Valledupar|Infraestructura Rural
A9: San Vicente del Caguan | B9: Caqueta | C9: 8 | D9: San Vicente del Caguan|Educacion | F9: MEJORA DEL RELACIONAMIENTO (Rubrica Objetiva)
A10: San Vicente del Caguan | B10: Caqueta | C10: 6 | D10: San Vicente del Caguan|Salud | F10: 5 | G10: Sustancial | H10: Conflictos activos documentados que el proyecto resolveria. Comunidad con oposicion formal. Incluye participacion.
A11: San Vicente del Caguan | B11: Caqueta | C11: 9 | D11: San Vicente del Caguan|Infraestructura Rural | F11: 4 | G11: Confianza | H11: Desconfianza documentada sin conflicto activo. Proyecto fortalece acuerdos o crea canales de dialogo.
A12: Tumaco | B12: Narino | C12: 7 | D12: Tumaco|Educacion | F12: 3 | G12: Moderada | H12: Relacion neutral sin historial negativo. Genera visibilidad positiva y contacto institucional.
A13: Tumaco | B13: Narino | C13: 5 | D13: Tumaco|Salud | F13: 2 | G13: Limitada | H13: Comunidad ya tiene relacion funcional con ENLAZA. Beneficio marginal al relacionamiento.
A14: Tumaco | B14: Narino | C14: 10 | D14: Tumaco|Infraestructura Rural | F14: 1 | G14: No aporta | H14: No hay comunidades relevantes o el proyecto no genera interaccion con stakeholders.
A15: Tumaco | B15: Narino | C15: 8 | D15: Tumaco|Agua y Saneamiento
A16: Apartado | B16: Antioquia | C16: 6 | D16: Apartado|Educacion
A17: Apartado | B17: Antioquia | C17: 4 | D17: Apartado|Salud
A18: Apartado | B18: Antioquia | C18: 7 | D18: Apartado|Infraestructura Rural
A19: Tibú | B19: Norte de Santander | C19: 9 | D19: Tibú|Educacion
A20: Tibú | B20: Norte de Santander | C20: 7 | D20: Tibú|Salud
A21: Tibú | B21: Norte de Santander | C21: 10 | D21: Tibú|Infraestructura Rural
A22: El Tambo | B22: Cauca | C22: 8 | D22: El Tambo|Educacion
A23: El Tambo | B23: Cauca | C23: 6 | D23: El Tambo|Salud | F23: SCORING SROI (Funcion Logaritmica Continua)
A24: El Tambo | B24: Cauca | C24: 9 | D24: El Tambo|Infraestructura Rural | F24: < 1.0 | G24: RECHAZADO | H24: Score 0 - Destruye valor social (gate preservado)
A25: Chaparral | B25: Tolima | C25: 5 | D25: Chaparral|Educacion | F25: 1.0 | G25: 60 pts | H25: Punto de anclaje base
A26: Chaparral | B26: Tolima | C26: 4 | D26: Chaparral|Salud | F26: 1.5 | G26: 73 pts | H26: Score = 60 + 35*ln(1.5)/ln(3)
A27: Chaparral | B27: Tolima | C27: 7 | D27: Chaparral|Infraestructura Rural | F27: 2.0 | G27: 82 pts | H27: Score = 60 + 35*ln(2)/ln(3)
A28: Buenaventura | B28: Valle del Cauca | C28: 7 | D28: Buenaventura|Educacion | F28: 3.0 | G28: 95 pts | H28: Score = 60 + 35*ln(3)/ln(3) = 60+35
A29: Buenaventura | B29: Valle del Cauca | C29: 5 | D29: Buenaventura|Salud | F29: >= 5.0 | G29: 98 pts | H29: Techo maximo - requiere observaciones
A30: Buenaventura | B30: Valle del Cauca | C30: 8 | D30: Buenaventura|Infraestructura Rural | F30: > 7.0 | G30: 98 pts | H30: Alerta: verificar metodologia de calculo
A31: Buenaventura | B31: Valle del Cauca | C31: 9 | D31: Buenaventura|Agua y Saneamiento
A32: Ituango | B32: Antioquia | C32: 8 | D32: Ituango|Educacion
A33: Ituango | B33: Antioquia | C33: 6 | D33: Ituango|Salud
A34: Ituango | B34: Antioquia | C34: 10 | D34: Ituango|Infraestructura Rural
A35: Puerto Asis | B35: Putumayo | C35: 7 | D35: Puerto Asis|Educacion
A36: Puerto Asis | B36: Putumayo | C36: 5 | D36: Puerto Asis|Salud
A37: Puerto Asis | B37: Putumayo | C37: 9 | D37: Puerto Asis|Infraestructura Rural

Sheet Panel de Control
A1: PANEL DE CONTROL - ENLAZA GEB
A3: METRICAS GENERALES | F3: TOP 5 PROYECTOS POR SCORE
A4: Total Proyectos Registrados | C4: =COUNTA('Registro Proyectos'!B4:B53) -> 0 | F4: # | G4: Proyecto | H4: Score | I4: Nivel
A5: Presupuesto Total | C5: =SUM('Registro Proyectos'!D4:D53) -> 0 | F5: 1 | G5: =IFERROR(INDEX('Registro Proyectos'!B$4:B$53,MATCH(LARGE('Registro Proyectos'!AC$4:AC$53,1),'Registro Proyectos'!AC$4:AC$53,0)),"") | H5: =IFERROR(LARGE('Registro Proyectos'!AC$4:AC$53,1),"") | I5: =IF(H5="","",IF(H5>=85,"MUY ALTA",IF(H5>=70,"ALTA",IF(H5>=50,"MEDIA","BAJA"))))
A6: Beneficiarios Totales | C6: =SUM('Registro Proyectos'!E4:E53) -> 0 | F6: 2 | G6: =IFERROR(INDEX('Registro Proyectos'!B$4:B$53,MATCH(LARGE('Registro Proyectos'!AC$4:AC$53,2),'Registro Proyectos'!AC$4:AC$53,0)),"") | H6: =IFERROR(LARGE('Registro Proyectos'!AC$4:AC$53,2),"") | I6: =IF(H6="","",IF(H6>=85,"MUY ALTA",IF(H6>=70,"ALTA",IF(H6>=50,"MEDIA","BAJA"))))
A7: Score Promedio | C7: =IFERROR(AVERAGE('Registro Proyectos'!AC4:AC53),"") | F7: 3 | G7: =IFERROR(INDEX('Registro Proyectos'!B$4:B$53,MATCH(LARGE('Registro Proyectos'!AC$4:AC$53,3),'Registro Proyectos'!AC$4:AC$53,0)),"") | H7: =IFERROR(LARGE('Registro Proyectos'!AC$4:AC$53,3),"") | I7: =IF(H7="","",IF(H7>=85,"MUY ALTA",IF(H7>=70,"ALTA",IF(H7>=50,"MEDIA","BAJA"))))
A8: Proyectos PDET | C8: =COUNTIF('Registro Proyectos'!I4:I53,"SI") -> 0 | F8: 4 | G8: =IFERROR(INDEX('Registro Proyectos'!B$4:B$53,MATCH(LARGE('Registro Proyectos'!AC$4:AC$53,4),'Registro Proyectos'!AC$4:AC$53,0)),"") | H8: =IFERROR(LARGE('Registro Proyectos'!AC$4:AC$53,4),"") | I8: =IF(H8="","",IF(H8>=85,"MUY ALTA",IF(H8>=70,"ALTA",IF(H8>=50,"MEDIA","BAJA"))))
F9: 5 | G9: =IFERROR(INDEX('Registro Proyectos'!B$4:B$53,MATCH(LARGE('Registro Proyectos'!AC$4:AC$53,5),'Registro Proyectos'!AC$4:AC$53,0)),"") | H9: =IFERROR(LARGE('Registro Proyectos'!AC$4:AC$53,5),"") | I9: =IF(H9="","",IF(H9>=85,"MUY ALTA",IF(H9>=70,"ALTA",IF(H9>=50,"MEDIA","BAJA"))))
A10: DISTRIBUCION POR NIVEL DE PRIORIDAD
A11: MUY ALTA (>=85) | C11: =COUNTIF('Registro Proyectos'!AD4:AD53,"MUY ALTA") -> 0
A12: ALTA (70-84) | C12: =COUNTIF('Registro Proyectos'!AD4:AD53,"ALTA") -> 0
A13: MEDIA (50-69) | C13: =COUNTIF('Registro Proyectos'!AD4:AD53,"MEDIA") -> 0
A14: BAJA (<50) | C14: =COUNTIF('Registro Proyectos'!AD4:AD53,"BAJA") -> 0
A15: RECHAZADO | C15: =COUNTIF('Registro Proyectos'!AD4:AD53,"RECHAZADO") -> 0
A17: ESTADO EN COMITE
A18: Pendientes de Presentar | C18: =COUNTIF('Registro Proyectos'!AE4:AE53,"Pendiente") -> 0
A19: Presentados | C19: =COUNTIF('Registro Proyectos'!AE4:AE53,"Presentado") -> 0
A20: Aprobados | C20: =COUNTIF('Registro Proyectos'!AE4:AE53,"Aprobado") -> 0
A21: Rechazados | C21: =COUNTIF('Registro Proyectos'!AE4:AE53,"Rechazado") -> 0
A22: En Revision | C22: =COUNTIF('Registro Proyectos'!AE4:AE53,"En Revision") -> 0
A24: PROMEDIOS POR CRITERIO
A25: SROI (40%) | C25: =IFERROR(AVERAGE('Registro Proyectos'!M4:M53),"")
A26: Stakeholders (25%) | C26: =IFERROR(AVERAGE('Registro Proyectos'!S4:S53),"")
A27: Prob. CONFIS (20%) | C27: =IFERROR(AVERAGE('Evaluacion Detallada'!G3:G52),"")
A28: Riesgos (15%) | C28: =IFERROR(AVERAGE('Registro Proyectos'!AB4:AB53),"")
A30: NOTA METODOLOGICA
A31: Score Total = SROI(40%) + Stakeholders(25%) + Prob.CONFIS(20%) + Riesgos(15%) Arquitectura C aprobada 15-Nov-2025. Ajuste metodológico Feb-2026. SROI: Función logarítmica continua Score=60+35*ln(SROI)/ln(3). Gate <1=Rechazado. Techo=98. Riesgos: scoring inverso (Prob x Impacto). Factores contextuales como alertas informativas. Stakeholders: Rúbricas objetivas con criterios verificables vinculados a operación ENLAZA. Prob.CONFIS: Metodología CONFIS Anexo 2. Score=Grupo(20%)+((Terr+Sect)/20×100)(80%). 8 grupos.
A36: MÉTRICAS CONFIS
A37: Proyectos PDET | C37: =COUNTIF('Registro Proyectos'!I4:I53,"SI") -> 0
A38: Score Prom. Prob. CONFIS | C38: =IFERROR(AVERAGE('Evaluacion Detallada'!G3:G52),"")

Sheet Instrucciones
A1: INSTRUCCIONES DE USO
A3: COMO REGISTRAR UN PROYECTO
A4: 1. Ir a la hoja 'Registro Proyectos'
A5: 2. Llenar los campos en AZUL (son los datos de entrada)
A6: 3. Los campos en NEGRO se calculan automaticamente (no modificar)
A7: 4. Los campos con lista desplegable tienen opciones predefinidas
A9: CAMPOS OBLIGATORIOS
A10: - Nombre del Proyecto (col B)
A11: - Presupuesto (col D)
A12: - Valor SROI (col L) - usar decimales, ej: 2.5
A13: - Pertinencia Operacional (col O) - escala 1 a 5
A14: - Mejora Relacionamiento (col P) - escala 1 a 5
... A57: - Ver hoja 'Metodología CONFIS' para documentación completa de la metodología

Sheet Metodología CONFIS
A1: METODOLOGÍA CONFIS - Priorización Obras por Impuestos
A2: Basado en Anexo 2 del Documento CONFIS - Ajuste Feb 2026
A4: 1. GATE DE ELEGIBILIDAD
A5: Solo proyectos en municipios PDET y/o ZOMAC son elegibles para Obras por Impuestos.
A6: Proyectos fuera de estas categorías reciben nivel 'NO ELEGIBLE' y score = 0.
A8: 2. GRUPOS DE PRIORIZACIÓN CONFIS (Agotamiento Secuencial)
A9: Los proyectos se priorizan primero por grupo (1-8), luego por score CONFIS dentro del grupo.
A11: Grupo | B11: Tipo Municipio | C11: Estructuración | D11: Score Grupo | E11: Prioridad
A12: 1 | B12: PATR-PDET | C12: Contribuyente paga | D12: 100 | E12: Máxima
A13: 2 | B13: PATR-PDET | C13: Sin estruc. contribuyente | D13: 90 | E13: Muy Alta
A14: 3 | B14: PDET | C14: Contribuyente paga | D14: 80 | E14: Alta
A15: 4 | B15: PDET | C15: Sin estruc. contribuyente | D15: 70 | E15: Media-Alta
A16: 5 | B16: ZOMAC (alta pobreza) | C16: Contribuyente paga | D16: 55 | E16: Media
A17: 6 | B17: ZOMAC (alta pobreza) | C17: Sin estruc. contribuyente | D17: 45 | E17: Media-Baja
A18: 7 | B18: Amazonía | C18: Contribuyente paga | D18: 35 | E18: Baja
A19: 8 | B19: Amazonía | C19: Sin estruc. contribuyente | D19: 25 | E19: Muy Baja
A22: 3. ENFOQUE TERRITORIAL (IPM + MDM_inv + IICA + CULTIVOS)
A23: Puntaje = Promedio de 4 índices normalizados (1-10)
A24: - IPM: Índice de Pobreza Multidimensional
A25: - MDM invertido: Desempeño Municipal (invertido = peor desempeño mayor puntaje)
A26: - IICA: Incidencia del Conflicto Armado
A27: - CULTIVOS: Presencia de Cultivos Ilícitos
A28: Nota: Si no se dispone de datos territoriales, se usa puntaje por defecto = 5.0
A30: 4. ENFOQUE SECTORIAL (Brechas por línea de inversión)
A31: Puntaje = Brecha del sector en el municipio (1-10, de matriz PDET/ZOMAC)
A32: - Educación
A33: - Salud y Protección Social
A34: - Agua Potable y Saneamiento
... A51: 6. EJEMPLOS DE CÁLCULO
A52: Ejemplo 1: | B52: Proyecto PATR-PDET, contribuyente paga, sectorial=10, territorial=8
B53: Grupo 1 (score=100), CONFIS=(8+10)/20x100=90
B54: Score Criterio 3 = 100x0.20 + 90x0.80 = 20 + 72 = 92
A56: Ejemplo 2: | B56: Proyecto PDET sin PATR, sin estruc., sectorial=5, territorial=5
B57: Grupo 4 (score=70), CONFIS=(5+5)/20x100=50
B58: Score Criterio 3 = 70x0.20 + 50x0.80 = 14 + 40 = 54
A60: Ejemplo 3: | B60: Proyecto ZOMAC, contribuyente paga, sectorial=8, territorial=6
B61: Grupo 5 (score=55), CONFIS=(6+8)/20x100=70
B62: Score Criterio 3 = 55x0.20 + 70x0.80 = 11 + 56 = 67
A65: 7. IMPLEMENTACIÓN
A66: MOTOR PYTHON (motor_arquitectura_c.py):
...
